"C:\Users\Alfeo Jr\OneDrive\Desktop\Porfolio Projects\FAQ_Agentic_Chatbot\.venv\Scripts\python.exe" "C:\Users\Alfeo Jr\OneDrive\Desktop\Porfolio Projects\FAQ_Agentic_Chatbot\testing_chat_before_deleting\docs_to_vector_to_llm_testing_only.py"
C:\Users\Alfeo Jr\OneDrive\Desktop\Porfolio Projects\FAQ_Agentic_Chatbot\.venv\Lib\site-packages\huggingface_hub\file_download.py:144: UserWarning: `huggingface_hub` cache-system uses symlinks by default to efficiently store duplicated files but your machine does not support them in C:\Users\Alfeo Jr\AppData\Local\llama_index\models--sentence-transformers--all-mpnet-base-v2. Caching files will still work but in a degraded version that might require more space on your disk. This warning can be disabled by setting the `HF_HUB_DISABLE_SYMLINKS_WARNING` environment variable. For more details, see https://huggingface.co/docs/huggingface_hub/how-to-cache#limitations.
To support symlinks on Windows, you either need to activate Developer Mode or to run Python as an administrator. In order to activate developer mode, see this article: https://docs.microsoft.com/en-us/windows/apps/get-started/enable-your-device-for-development
  warnings.warn(message)
Xet Storage is enabled for this repo, but the 'hf_xet' package is not installed. Falling back to regular HTTP download. For better performance, install the package with: `pip install huggingface_hub[hf_xet]` or `pip install hf_xet`
2025-05-09 14:23:41,972 [DEBUG][_create_connection]: Created new connection using: c5ff625cfd8d4897bf5efaaf80b09425 (async_milvus_client.py:599)
Traceback (most recent call last):
  File "C:\Users\Alfeo Jr\OneDrive\Desktop\Porfolio Projects\FAQ_Agentic_Chatbot\testing_chat_before_deleting\docs_to_vector_to_llm_testing_only.py", line 36, in <module>
    index = VectorStoreIndex.from_documents(
        nodes=nodes,
        embed_model=embed_model,
        storage_context=storage_context
    )
TypeError: BaseIndex.from_documents() missing 1 required positional argument: 'documents'
Error in sys.excepthook:

Original exception was:

Process finished with exit code 1
